<?xml version="1.0" ?>

<robot name="robot" xmlns:xacro="http://www.ros.org/wiki/xacro">
  <material name="white">
    <color rgba="1 1 1 1"/>
  </material>
  <material name="orange">
    <color rgba="1 0.3 0.1 1"/>
  </material>
  <material name="blue">
    <color rgba="0.2 0.2 1 1"/>
  </material>
  <material name="black">
    <color rgba="0 0 0 1"/>
  </material>
  <!-- BASE LINK -->
  <link name="base_link">
    </link>
    

  <!-- CHASSIS LINK -->
  <joint name="chassis_joint" type="fixed">
    <parent link="base_link"/>
    <child link="chassis"/>
    <origin xyz="0.032 0 0"/>
  </joint>
  <link name="chassis">
    <visual>
      <origin xyz="0 0 0"/>
      <geometry>
       <mesh filename="package://bot/models/meshes/turtle1.dae" scale="0.001 0.001 0.001"/>
       <!--<mesh filename="model://articubot_one/meshes/meshes/turtle1.stl" scale="0.25 0.25 0.25"/>-->
      </geometry>
    </visual>
    <collision>
      <origin xyz="0 0 0.08"/>
      <geometry>
        <!--            <mesh filename="package://articubot_one/meshes/turtle1.stl" scale="0.25 0.25 0.25"/>
 -->
        <cylinder length="0.16" radius="0.08"/>
      </geometry>
    </collision>
    <inertial>
      <origin rpy="0 0 0" xyz="0.075 0 0.0"/>
      <mass value="0.4"/>
      <inertia ixx="0.019255208333333336" ixy="0.0" ixz="0.0" iyy="0.019255208333333336" iyz="0.0" izz="0.03200000000000001"/>
    </inertial>
  </link>
  <gazebo reference="chassis">
      <material>Gazebo/Yellow</material>
  </gazebo>
  
  
  <!-- LEFT WHEEL LINK -->
  <joint name="left_wheel_joint" type="continuous">
    <parent link="base_link"/>
    <child link="left_wheel"/>
    <origin rpy="-1.5707963267948966 0 0" xyz="0 0.053 0.023"/>
    <axis xyz="0 0 1"/>
  </joint>
  <link name="left_wheel">
    <visual>
      <geometry>
        <cylinder length="0.01" radius="0.04"/>
      </geometry>
      <material name="black"/>
    </visual>
    <collision>
      <geometry>
        <cylinder length="0.01" radius="0.04"/>
      </geometry>
    </collision>
    <inertial>
      <origin rpy="0 0 0" xyz="0 0 0"/>
      <mass value="0.1"/>
      <inertia ixx="0.0002533333333333334" ixy="0.0" ixz="0.0" iyy="0.0002533333333333334" iyz="0.0" izz="0.0005000000000000001"/>
    </inertial>
  </link>
  <gazebo reference="left_wheel">
      <material>Gazebo/Black</material>
  </gazebo>
  
  
  <!-- RIGHT WHEEL LINK -->
  <joint name="right_wheel_joint" type="continuous">
    <parent link="base_link"/>
    <child link="right_wheel"/>
    <origin rpy="1.5707963267948966 0 0" xyz="0 -0.053 0.023"/>
    <axis xyz="0 0 -1"/>
  </joint>
  <link name="right_wheel">
    <visual>
      <geometry>
        <cylinder length="0.01" radius="0.04"/>
      </geometry>
      <material name="black"/>
    </visual>
    <collision>
      <geometry>
        <cylinder length="0.01" radius="0.04"/>
      </geometry>
    </collision>
    <inertial>
      <origin rpy="0 0 0" xyz="0 0 0"/>
      <mass value="0.1"/>
      <inertia ixx="0.0002533333333333334" ixy="0.0" ixz="0.0" iyy="0.0002533333333333334" iyz="0.0" izz="0.0005000000000000001"/>
    </inertial>
  </link>
  <gazebo reference="right_wheel">
      <material>Gazebo/Black</material>
  </gazebo>
  
  <!-- CASTER WHEEL LINK -->
  <joint name="caster_wheel_joint" type="fixed">
    <parent link="chassis"/>
    <child link="caster_wheel"/>
    <origin xyz="0.064 0 0"/>
  </joint>
  <link name="caster_wheel">
    <visual>
      <geometry>
        <sphere radius="0.015"/>
      </geometry>
      <material name="black"/>
    </visual>
    <collision>
      <geometry>
        <sphere radius="0.015"/>
      </geometry>
    </collision>
    <inertial>
      <origin rpy="0 0 0" xyz="0 0 0"/>
      <mass value="0.1"/>
      <inertia ixx="0.00010000000000000005" ixy="0.0" ixz="0.0" iyy="0.00010000000000000005" iyz="0.0" izz="0.00010000000000000005"/>
    </inertial>
  </link>
  <gazebo reference="caster_wheel">
      <material>Gazebo/Grey</material>
  </gazebo>
    <gazebo>
        <plugin name="diff_drive" filename="libgazebo_ros_diff_drive.so">

            <!-- Wheel Information -->
            <left_joint>left_wheel_joint</left_joint>
            <right_joint>right_wheel_joint</right_joint>
            <wheel_separation>0.27</wheel_separation>
            <wheel_diameter>0.2</wheel_diameter>


            <!-- Limits -->
            <max_wheel_torque>200</max_wheel_torque>
            <max_wheel_acceleration>10.0</max_wheel_acceleration>

            
            <!-- Output -->
            <odometry_frame>odom</odometry_frame>
            <robot_base_frame>base_link</robot_base_frame>

            <publish_odom>true</publish_odom>
            <publish_odom_tf>true</publish_odom_tf>
            <publish_wheel_tf>true</publish_wheel_tf>

        </plugin>
    </gazebo>
    
</robot>

