<?xml version="1.0" ?>
<sdf version="1.6">
    <model name='bumblebee' canonical_link='base_link'>
        <pose>0 0 0.02 0 0 0</pose>

        <link name="base_footprint"/>

        <link name="base_link">

            <inertial>
                <pose>0.032 0 0 0 0 0</pose>
                <inertia>
                    <ixx>7.2397393e-01</ixx>
                    <ixy>4.686399e-10</ixy>
                    <ixz>-1.09525703e-08</ixz>
                    <iyy>7.2397393e-01</iyy>
                    <iyz>2.8582649e-09</iyz>
                    <izz>6.53050163e-01</izz>
                </inertia>
                <mass>8.2573504e-01</mass>
            </inertial>

            <collision name="base_collision">
                <pose>0.032 0 0 0 0 0</pose>
                <geometry>
                    <box>
                        <size>0.140 0.140 0.140</size>
                    </box>
                </geometry>
            </collision>

            <visual name="base_visual">
                <pose>0.032 0 0 0 0 0</pose>
                <geometry>
                    <mesh>
                        <uri>meshes/turtle1.dae</uri>
                        <scale>0.001 0.001 0.001</scale>
                    </mesh>
                </geometry>
            </visual>
        </link>

        <joint name="base_joint" type="fixed">
            <parent>base_footprint</parent>
            <child>base_link</child>
            <pose>0.0 0.0 0.010 0 0 0</pose>
        </joint>

        <!-- Left Wheel Link -->
        <joint name="left_wheel_joint" type="revolute">
            <parent>base_link</parent>
            <child>left_wheel_link</child>
            <pose>0.0 0.053 0.023 -1.57 0 0</pose>
            <axis>
                <xyz>0 0 1</xyz>
                <limit>
                    <effort>20</effort>                    <!-- from <wheel_torque> in libgazebo_ros_diff_drive.so.-->
                </limit>
            </axis>
        </joint>

        <link name="left_wheel_link">

            <inertial>
                <pose>0 0.053 0.023 -1.57 0 0</pose>
                <inertia>
                    <ixx>1.8158194e-03</ixx>
                    <ixy>-9.3392e-12</ixy>
                    <ixz>1.04909e-11</ixz>
                    <iyy>3.2922126e-03</iyy>
                    <iyz>5.75694e-11</iyz>
                    <izz>1.8158194e-03</izz>
                </inertia>
                <mass>2.8498940e-02</mass>
            </inertial>

            <collision name="left_wheel_collision">
                <pose>0 0.053 0.023 -1.57 0 0</pose>
                <geometry>
                    <cylinder>
                        <radius>0.04</radius>
                        <length>0.01</length>
                    </cylinder>
                </geometry>
                <surface>
                    <!-- This friction pamareter don't contain reliable data!! -->
                    <friction>
                        <ode>
                            <mu>100000.0</mu>
                            <mu2>100000.0</mu2>
                            <fdir1>0 0 0</fdir1>
                            <slip1>0.0</slip1>
                            <slip2>0.0</slip2>
                        </ode>
                    </friction>
                    <contact>
                        <ode>
                            <soft_cfm>0</soft_cfm>
                            <soft_erp>0.2</soft_erp>
                            <kp>1e+5</kp>
                            <kd>1</kd>
                            <max_vel>0.01</max_vel>
                            <min_depth>0.001</min_depth>
                        </ode>
                    </contact>
                </surface>
            </collision>

            <visual name="left_wheel_visual">
                <pose>0 0.053 0.023 -1.57 0 0</pose>
                <geometry>
                    <cylinder>
                        <radius>0.04</radius>
                        <length>0.01</length>
                    </cylinder>
                </geometry>
                <material>
                    <ambient>0.2 0.2 0.2 1</ambient>
                    <diffuse>0.2 0.2 0.2 1</diffuse>
                    <specular>1 1 1 1</specular>
                </material>
            </visual>
        </link>

        <!-- Right Wheel Link -->
        <joint name="right_wheel_joint" type="revolute">
            <parent>base_link</parent>
            <child>right_wheel_link</child>
            <pose>0.0 -0.053 0.023 -1.57 0 0</pose>
            <axis>
                <xyz>0 0 -1</xyz>
                <limit>
                    <effort>20</effort>                    <!-- from <wheel_torque> in libgazebo_ros_diff_drive.so.-->
                </limit>
            </axis>
        </joint>

        <link name="right_wheel_link">
            <inertial>
                <pose>0.0 -0.053 0.023 -1.57 0 0</pose>
                <inertia>
                    <ixx>1.8158194e-03</ixx>
                    <ixy>-9.3392e-12</ixy>
                    <ixz>1.04909e-11</ixz>
                    <iyy>3.2922126e-03</iyy>
                    <iyz>5.75694e-11</iyz>
                    <izz>1.8158194e-03</izz>
                </inertia>
                <mass>2.8498940e-02</mass>
            </inertial>
            <collision name="right_wheel_collision">
                <pose>0.0 -0.053 0.023 -1.57 0 0</pose>
                <geometry>
                    <cylinder>
                        <radius>0.04</radius>
                        <length>0.01</length>
                    </cylinder>
                </geometry>
                <surface>
                    <!-- This friction pamareter don't contain reliable data!! -->
                    <friction>
                        <ode>
                            <mu>100000.0</mu>
                            <mu2>100000.0</mu2>
                            <fdir1>0 0 0</fdir1>
                            <slip1>0.0</slip1>
                            <slip2>0.0</slip2>
                        </ode>
                    </friction>
                    <contact>
                        <ode>
                            <soft_cfm>0</soft_cfm>
                            <soft_erp>0.2</soft_erp>
                            <kp>1e+5</kp>
                            <kd>1</kd>
                            <max_vel>0.01</max_vel>
                            <min_depth>0.001</min_depth>
                        </ode>
                    </contact>
                </surface>
            </collision>
            <visual name="right_wheel_visual">
                <pose>0.0 -0.053 0.023 -1.57 0 0</pose>
                <geometry>
                    <cylinder>
                        <radius>0.04</radius>
                        <length>0.01</length>
                    </cylinder>
                </geometry>
                <material>
                    <ambient>0.2 0.2 0.2 1</ambient>
                    <diffuse>0.2 0.2 0.2 1</diffuse>
                    <specular>1 1 1 1</specular>
                </material>
            </visual>
        </link>

        <!-- Caster Wheel Link -->
        <joint name='caster_wheel_joint' type='ball'>
            <parent>base_link</parent>
            <child>caster_wheel_link</child>
        </joint>

        <link name='caster_wheel_link'>
            <pose>0.093 0 0 -1.57 0 0</pose>
            <inertial>
                <mass>0.005</mass>
                <inertia>
                    <ixx>0.001</ixx>
                    <ixy>0.000</ixy>
                    <ixz>0.000</ixz>
                    <iyy>0.001</iyy>
                    <iyz>0.000</iyz>
                    <izz>0.001</izz>
                </inertia>
            </inertial>
            <collision name='collision'>
                <geometry>
                    <sphere>
                        <radius>0.015</radius>
                    </sphere>
                </geometry>
                <surface>
                    <contact>
                        <ode>
                            <soft_cfm>0</soft_cfm>
                            <soft_erp>0.2</soft_erp>
                            <kp>1e+5</kp>
                            <kd>1</kd>
                            <max_vel>0.01</max_vel>
                            <min_depth>0.001</min_depth>
                        </ode>
                    </contact>
                </surface>
            </collision>
            <visual name='castor_visual'>
                <geometry>
                    <sphere>
                        <radius>0.015</radius>
                    </sphere>
                </geometry>
            </visual>
        </link>



        <plugin filename="gz-sim-diff-drive-system" name="gz::sim::systems::DiffDrive">

            <!-- wheels -->
            <left_joint>left_wheel_joint</left_joint>
            <right_joint>right_wheel_joint</right_joint>
            <joint_name>caster_wheel_joint</joint_name>

            <!-- kinematics -->
            <wheel_separation>0.106</wheel_separation>
            <wheel_radius>0.08</wheel_radius>            <!-- computed from <wheel_diameter> in the original plugin-->

            <!-- limits -->
            <max_linear_acceleration>0.033</max_linear_acceleration>            <!-- computed from <max_linear_acceleration> in the original plugin-->

            <topic>cmd_vel</topic>            <!-- from <commant_topic> -->

            <odom_topic>odom</odom_topic>            <!-- from <odometry_topic> -->
            <frame_id>odom</frame_id>            <!-- from <odometry_frame> -->
            <child_frame_id>base_footprint</child_frame_id>            <!-- from <robot_base_frame> -->
            <odom_publisher_frequency>30</odom_publisher_frequency>            <!-- from <update_rate>-->

            <tf_topic>/tf</tf_topic>            <!-- Short topic name for tf output -->

        </plugin>

        <plugin filename="gz-sim-joint-state-publisher-system" name="gz::sim::systems::JointStatePublisher">
            <topic>joint_states</topic>            <!--from <ros><remapping> -->
            <joint_name>left_wheel_joint</joint_name>
            <joint_name>right_wheel_joint</joint_name>
            <joint_name>caster_wheel_joint</joint_name>
        </plugin>
    </model>
</sdf>
